Workbook

Sheet Nutrition
A1: Ingredient | B1: Amount (Meal) | C1: Amount (USDA) | D1: Calories | E1: Fat | F1: Sodium | G1: Carbs | H1: Protein | I1: Link
A2: USDA: https://fdc.nal.usda.gov/ *if you cant find it on usda, just go to nutrition info on the website link*
A3: Baked Feta Pasta - Taryn
A4: Baby Spinach | B4: 1 bag | C4: 100g | D4: 32.2kcal | E4: 0.6g | F4: 110.6mg | G4: 5.0g | H4: 4.1g | I4: Spinach, baby - Components - Foundation | USDA FoodData Central
A5: Cherry Tomatoes | B5: 1 container | C5: 100g | D5: 50.4kcal | E5: 0.6g | F5: 14.0mg | G5: 10.9g | H5: 2.5g | I5: Pasta, dry, enriched - Nutrients - SR Legacy | USDA FoodData Central
A6: Feta block | B6: 1 container | C6: 100g | D6: 596.6kcal | E6: 47.5g | F6: 2072.4mg | G6: 9.3g | H6: 31.6g | I6: Cheese, feta - Nutrients - SR Legacy | USDA FoodData Central
A7: Olive oil | B7: 2 tbsp | C7: 1tbsp | D7: 238.0kcal | E7: 28.0g | F7: 0.0mg | G7: 0.0g | H7: 0.0g | I7: Oil, olive, salad or cooking - Nutrients - SR Legacy | USDA FoodData Central
A8: Salt/Pepper | B8: generous amount | C8: 1tsp | D8: 0.0kcal | E8: 0.0g | F8: 2300.0mg | G8: 0.0g | H8: 0.0g | I8: Salt, table, iodized - Nutrients - Foundation | USDA FoodData Central | J8: Spices, pepper, black - Nutrients - SR Legacy | USDA FoodData Central
A9: Minced garlic | B9: 2 tbsp | C9: 1tbsp | D9: 30.0kcal | E9: 0.0g | F9: 2.0mg | G9: 6.0g | H9: 2.0g | I9: Garlic, raw - Nutrients - Foundation | USDA FoodData Central
A10: Pasta | B10: 8 oz | C10: 1oz_dry | D10: 800.0kcal | E10: 4.0g | F10: 0.0mg | G10: 168.0g | H10: 28.0g | I10: Pasta, dry, enriched - Nutrients - SR Legacy | USDA FoodData Central
A11: Totals/Meal Total
A12: Recipe Reference: https://thespicegirlkitchen.com/creamy-salmon-pasta/
A14: Overnight Oats - Taryn
A15: Old fashioned oats | B15: 1/4 cup | C15: 1/4 cup | D15: 37.5kcal | E15: 0.6g | F15: 0.0mg | G15: 6.8g | H15: 1.2g | I15: Oats, whole grain, rolled, old fashioned - Nutrients - Foundation | USDA FoodData Central
A16: Greek yogurt | B16: 1/4 cup | C16: 1/4 cup | D16: 7.5kcal | E16: 0.0g | F16: 3.8mg | G16: 0.4g | H16: 1.1g | I16: Yogurt, Greek, plain, nonfat - Nutrients - Foundation | USDA FoodData Central
A17: Milk (2%?) | B17: 1/3 cup | C17: 1 cup | D17: 40.7kcal | E17: 1.6g | F17: 38.3mg | G17: 4.0g | H17: 2.7g | I17: Milk, reduced fat, fluid, 2% milkfat, with added vitamin A and vitamin D - Nutrients - Foundation | USDA FoodData Central
A18: Chia Seeds | B18: 2 tsp | C18: 2 tsp | D18: 200.0kcal | E18: 12.0g | F18: 6.0mg | G18: 16.0g | H18: 7.0g | I18: Chia seeds, dry, raw - Nutrients - Foundation | USDA FoodData Central
A19: Blueberries | B19: 1/4 cup | C19: 1/4 cup | D19: 5.2kcal | E19: 0.0g | F19: 0.0mg | G19: 1.2g | H19: 0.1g | I19: Chia seeds, dry, raw - Nutrients - Foundation | USDA FoodData Central
A20: Honey | B20: 2 tsp | C20: 1 tsp | D20: 42.0kcal | E20: 0.0g | F20: 0.0mg | G20: 12.0g | H20: 0.0g | I20: Honey - Nutrients - SR Legacy | USDA FoodData Central
A21: Totals/Meal Total
A22: Recipe reference: https://www.allrecipes.com/recipe/244251/no-cook-overnight-oatmeal/
A24: Quesidilla - Liliana
A25: Tortilla (Large?) | B25: 8 | C25: 1 piece | D25: 1680.0kcal | E25: 40.0g | F25: 3600.0mg | G25: 280.0g | H25: 48.0g | I25: Tortillas, ready-to-bake or -fry, flour, shelf stable
A26: Butter | B26: 1 tbs | C26: 1 tbsp | D26: 102.0kcal | E26: 12.0g | F26: 90.0mg | G26: 0.0g | H26: 0.1g | I26: Butter, salted
A27: Chicken breast | B27: 2 breasts | C27: 100g_raw | D27: 240.0kcal | E27: 5.2g | F27: 90.0mg | G27: 0.0g | H27: 46.0g | I27: Chicken, breast, boneless, skinless, raw
A28: Black beans | B28: 1 can | C28: 1 cup | D28: 340.5kcal | E28: 1.5g | F28: 15.0mg | G28: 61.5g | H28: 22.5g | I28: Beans, black, canned, sodium added, drained and rinsed
A29: Shredded cheddar cheese | B29: 1/4 cup | C29: 1 cup | D29: 113.8kcal | E29: 9.2g | F29: 175.5mg | G29: 0.4g | H29: 7.0g | I29: Cheese, cheddar
A30: Salt/Pepper | B30: 1 tsp | C30: 1tsp | D30: 0.0kcal | E30: 0.0g | F30: 2300.0mg | G30: 0.0g | H30: 0.0g | I30: Repeat Item
A31: Olive oil (sub with vegetable) | B31: 1 Tbs | C31: 1tbsp | D31: 119.0kcal | E31: 14.0g | F31: 0.0mg | G31: 0.0g | H31: 0.0g | I31: Repeat Item
A32: Totals/Meal Total
A33: Recipe Reference:
A35: Taco Soup - Liliana
A36: Ground Beef | B36: 1lb | C36: 1 lb | D36: 1152.0kcal | E36: 91.0g | F36: 300.0mg | G36: 0.0g | H36: 78.0g | I36: Beef, grass-fed, ground, raw
A37: Onion (yellow?) | B37: 1 | C37: 1 medium | D37: 45.0kcal | E37: 0.1g | F37: 5.0mg | G37: 11.0g | H37: 1.2g | I37: Onions, yellow, raw
A38: Diced tomatos | B38: 1 can | C38: 1 can_14.5oz | D38: 100.0kcal | E38: 0.0g | F38: 600.0mg | G38: 22.0g | H38: 4.0g | I38: Tomatoes, canned, red, ripe, diced
A39: Taco seasoning | B39: 1 packet | C39: 1 packet | D39: 90.0kcal | E39: 0.0g | F39: 2200.0mg | G39: 18.0g | H39: 0.0g | I39: Seasoning mix, dry, taco, original
A40: Kidney beans | B40: 1 can | C40: 1 cup | D40: 322.5kcal | E40: 1.5g | F40: 15.0mg | G40: 55.5g | H40: 19.5g | I40: Kidney beans, from canned, no added fat
A41: Sweet corn | B41: 1 can | C41: 1 can_15oz | D41: 280.0kcal | E41: 4.0g | F41: 800.0mg | G41: 60.0g | H41: 8.0g | I41: Corn, sweet, white, canned, whole kernel, drained solids
A42: Salt/Pepper | B42: A pinch | C42: 1tsp | D42: 0.0kcal | E42: 0.0g | F42: 2300.0mg | G42: 0.0g | H42: 0.0g | I42: Repeat Item
A43: Shredded cheddar cheese | B43: 1.5 cup bag | C43: 1 cup | D43: 455.0kcal | E43: 37.0g | F43: 702.0mg | G43: 1.5g | H43: 28.0g | I43: Repeat Item
...

Sheet Master
A1: Ingredient | B1: Quantity | C1: Wegmans | D1: TJs | E1: McLanahas | F1: Weis | G1: Target D | H1: Giant | I1: Sams Club | J1: Target U | K1: Aldi | L1: Walmart
A3: Baked Feta Pasta - Taryn | Q3: 6
A4: Baby Spinach | B4: 1 bag | C4: ='Wegmans (F)'!E4 -> 3.29 | D4: ='Trader Joes (F)'!E4 -> 2.29 | E4: ='Mclanahans (N)'!E4 -> 2.99 | F4: ='Weis (N)'!E4 -> 1.52 | G4: ='Target D (T)'!E4 -> 2.19 | H4: ='Giant (T)'!E4 -> 3.49 | I4: ='Sams Club (N)'!E4 -> 2.38 | J4: ='Target Up (N)'!E4 -> 2.29 | K4: ='Aldi (L)'!E4 -> 2.85 | L4: ='Walmart (L)'!E4 -> 2.18
A5: Cherry Tomatoes | B5: 1 container | C5: ='Wegmans (F)'!E5 -> 6.49 | D5: ='Trader Joes (F)'!E5 -> 4.99 | E5: ='Mclanahans (N)'!E5 -> 2.89 | F5: ='Weis (N)'!E5 -> 2.49 | G5: ='Target D (T)'!E5 -> 2.59 | H5: ='Giant (T)'!E5 -> 4.99 | I5: ='Sams Club (N)'!E5 -> 2.7708333 | J5: ='Target Up (N)'!E5 -> 2.49 | K5: ='Aldi (L)'!E5 -> 2.19 | L5: ='Walmart (L)'!E5 -> 2.63
A6: Feta block | B6: 1 container | C6: ='Wegmans (F)'!E6 -> 4.99 | D6: ='Trader Joes (F)'!E6 -> 3.79 | E6: ='Mclanahans (N)'!E6 -> NA | F6: ='Weis (N)'!E6 -> 4.99 | G6: ='Target D (T)'!E6 -> 5.29 | H6: ='Giant (T)'!E6 -> 3.99 | I6: ='Sams Club (N)'!E6 -> 2.44 | J6: ='Target Up (N)'!E6 -> 5.29 | K6: ='Aldi (L)'!E6 -> 3.85 | L6: ='Walmart (L)'!E6 -> 5.46
A7: Olive oil | B7: 2 tbsp | C7: ='Wegmans (F)'!E7 -> 0.29 | D7: ='Trader Joes (F)'!E7 -> 0.3 | E7: ='Mclanahans (N)'!E7 -> 0.52 | F7: ='Weis (N)'!E7 -> 0.69 | G7: ='Target D (T)'!E7 -> 0.38727273 | H7: ='Giant (T)'!E7 -> 0.42363636 | I7: ='Sams Club (N)'!E7 -> 0.19201183 | J7: ='Target Up (N)'!E7 -> 0.37810651 | K7: ='Aldi (L)'!E7 -> 0.36764706 | L7: ='Walmart (L)'!E7 -> 0.34941176
A8: Salt/Pepper | B8: generous amount | C8: ='Wegmans (F)'!E8 -> 0.01 | D8: ='Trader Joes (F)'!E8 -> 0.01 | E8: ='Mclanahans (N)'!E8 -> 0.1 | F8: ='Weis (N)'!E8 -> 0.1 | G8: ='Target D (T)'!E8 -> 0.056056338 | H8: ='Giant (T)'!E8 -> 0.11211268 | I8: ='Sams Club (N)'!E8 -> 0.0775 | J8: ='Target Up (N)'!E8 -> 0.146 | K8: ='Aldi (L)'!E8 -> 0.145625 | L8: ='Walmart (L)'!E8 -> 0.01
A9: Minced garlic | B9: 2 tbsp | C9: ='Wegmans (F)'!E9 -> 0.44 | D9: ='Trader Joes (F)'!E9 -> 0 | E9: ='Mclanahans (N)'!E9 -> 0.49 | F9: ='Weis (N)'!E9 -> 0.32 | G9: ='Target D (T)'!E9 -> 0.66444444 | H9: ='Giant (T)'!E9 -> 0.6225 | I9: ='Sams Club (N)'!E9 -> 0.11833333 | J9: ='Target Up (N)'!E9 -> 0.47375 | K9: ='Aldi (L)'!E9 -> 0.35625 | L9: ='Walmart (L)'!E9 -> 0.51023192
A10: Pasta | B10: 8 oz | C10: ='Wegmans (F)'!E10 -> 0.5 | D10: ='Trader Joes (F)'!E10 -> 1 | E10: ='Mclanahans (N)'!E10 -> 1.28 | F10: ='Weis (N)'!E10 -> 0.83 | G10: ='Target D (T)'!E10 -> 0.495 | H10: ='Giant (T)'!E10 -> 0.5 | I10: ='Sams Club (N)'!E10 -> 0.71 | J10: ='Target Up (N)'!E10 -> 0.495 | K10: ='Aldi (L)'!E10 -> 1.045 | L10: ='Walmart (L)'!E10 -> 0.49
A11: Totals/Meal Total | C11: ='Wegmans (F)'!E11 -> 16.01 | D11: ='Trader Joes (F)'!E11 -> 12.38 | E11: ='Mclanahans (N)'!E11 -> 8.27 | F11: ='Weis (N)'!E11 -> 10.94 | G11: ='Target D (T)'!E11 -> 11.672774 | H11: ='Giant (T)'!E11 -> 14.128249 | I11: ='Sams Club (N)'!E11 -> 8.6886785 | J11: ='Target Up (N)'!E11 -> 11.562857 | K11: ='Aldi (L)'!E11 -> 10.804522 | L11: ='Walmart (L)'!E11 -> 11.629644
A12: Recipe Reference: https://thespicegirlkitchen.com/creamy-salmon-pasta/
A14: Overnight Oats - Taryn | Q14: 1
A15: Old fashioned oats | B15: 1/4 cup | C15: ='Wegmans (F)'!E15 -> 0.07 | D15: ='Trader Joes (F)'!E15 -> 0.33 | E15: ='Mclanahans (N)'!E15 -> NA | F15: ='Weis (N)'!E15 -> 0.12 | G15: ='Target D (T)'!E15 -> 0.22230769 | H15: ='Giant (T)'!E15 -> 0.0665 | I15: ='Sams Club (N)'!E15 -> 0.09975 | J15: ='Target Up (N)'!E15 -> 0.93142857 | K15: ='Aldi (L)'!E15 -> 0.21666667 | L15: ='Walmart (L)'!E15 -> 0.10230769
A16: Greek yogurt | B16: 1/4 cup | C16: ='Wegmans (F)'!E16 -> 0.09 | D16: ='Trader Joes (F)'!E16 -> 0.37 | E16: ='Mclanahans (N)'!E16 -> 0.56 | F16: ='Weis (N)'!E16 -> 0.37 | G16: ='Target D (T)'!E16 -> 0.226 | H16: ='Giant (T)'!E16 -> 0.25266667 | I16: ='Sams Club (N)'!E16 -> 0.20708333 | J16: ='Target Up (N)'!E16 -> 1.4975 | K16: ='Aldi (L)'!E16 -> 0.205625 | L16: ='Walmart (L)'!E16 -> 0.41
A17: Milk (2%?) | B17: 1/3 cup | C17: ='Wegmans (F)'!E17 -> 0.1 | D17: ='Trader Joes (F)'!E17 -> 0 | E17: ='Mclanahans (N)'!E17 -> 0.1 | F17: ='Weis (N)'!E17 -> 0.15 | G17: ='Target D (T)'!E17 -> 0.101875 | H17: ='Giant (T)'!E17 -> 0.135 | I17: ='Sams Club (N)'!E17 -> 0.1780791 | J17: ='Target Up (N)'!E17 -> 0.11208333 | K17: ='Aldi (L)'!E17 -> 0.11625 | L17: ='Walmart (L)'!E17 -> 0.19666667
A18: Chia Seeds | B18: 2 tsp | C18: ='Wegmans (F)'!E18 -> 0.1 | D18: ='Trader Joes (F)'!E18 -> 0 | E18: ='Mclanahans (N)'!E18 -> 0.18 | F18: ='Weis (N)'!E18 -> 0.14 | G18: ='Target D (T)'!E18 -> NA | H18: ='Giant (T)'!E18 -> 0.23955556 | I18: ='Sams Club (N)'!E18 -> N/A | J18: ='Target Up (N)'!E18 -> 0.33291667 | K18: ='Aldi (L)'!E18 -> 0.11361111 | L18: ='Walmart (L)'!E18 -> 0.17644444
A19: Blueberries | B19: 1/4 cup | C19: ='Wegmans (F)'!E19 -> 0.5 | D19: ='Trader Joes (F)'!E19 -> 0.07 | E19: ='Mclanahans (N)'!E19 -> 0.42 | F19: ='Weis (N)'!E19 -> 0.39 | G19: ='Target D (T)'!E19 -> 0.49875 | H19: ='Giant (T)'!E19 -> 0.62375 | I19: ='Sams Club (N)'!E19 -> 0.29041667 | J19: ='Target Up (N)'!E19 -> 0.29083333 | K19: ='Aldi (L)'!E19 -> 0.2575 | L19: ='Walmart (L)'!E19 -> 0.265
A20: Honey | B20: 2 tsp | C20: ='Wegmans (F)'!E20 -> 10 | D20: ='Trader Joes (F)'!E20 -> 0 | E20: ='Mclanahans (N)'!E20 -> 0.1 | F20: ='Weis (N)'!E20 -> 0.21 | G20: ='Target D (T)'!E20 -> 0.18708333 | H20: ='Giant (T)'!E20 -> 0.15375 | I20: ='Sams Club (N)'!E20 -> 0.055416667 | J20: ='Target Up (N)'!E20 -> 0.13305556 | K20: ='Aldi (L)'!E20 -> 0.1025 | L20: ='Walmart (L)'!E20 -> 0.15583333
A21: Totals/Meal Total | C21: ='Wegmans (F)'!E21 -> 10.86 | D21: ='Trader Joes (F)'!E21 -> 0.77 | E21: ='Mclanahans (N)'!E21 -> 1.36 | F21: ='Weis (N)'!E21 -> 1.38 | G21: ='Target D (T)'!E21 -> 1.236016 | H21: ='Giant (T)'!E21 -> 1.4712222 | I21: ='Sams Club (N)'!E21 -> 0.83074576 | J21: ='Target Up (N)'!E21 -> 3.2978175 | K21: ='Aldi (L)'!E21 -> 1.0121528 | L21: ='Walmart (L)'!E21 -> 1.3062521
A22: Recipe reference: https://www.allrecipes.com/recipe/244251/no-cook-overnight-oatmeal/
A24: Quesidilla - Liliana | Q24: 4
A25: Tortilla (Large?) | B25: 8 | C25: ='Wegmans (F)'!E25 -> 2.49 | D25: ='Trader Joes (F)'!E25 -> 1.99 | E25: ='Mclanahans (N)'!E25 -> 3.49 | F25: ='Weis (N)'!E25 -> 2.69 | G25: ='Target D (T)'!E25 -> 1.99 | H25: ='Giant (T)'!E25 -> 2.99 | I25: ='Sams Club (N)'!E25 -> 1.2233333 | J25: {='Target Up (N)'!E25:E31} -> 4.69 | K25: ='Aldi (L)'!E25 -> 2.35 | L25: ='Walmart (L)'!E25 -> 2.12
A26: Butter | B26: 1 tbs | C26: ='Wegmans (F)'!E26 -> 0.16 | D26: ='Trader Joes (F)'!E26 -> 0 | E26: ='Mclanahans (N)'!E26 -> 0.19 | F26: ='Weis (N)'!E26 -> 0.12 | G26: ='Target D (T)'!E26 -> 0.1153125 | H26: ='Giant (T)'!E26 -> 0.1028125 | I26: ='Sams Club (N)'!E26 -> 0.0659375 | J26: 0.1090625 | K26: ='Aldi (L)'!E26 -> 0.1028125 | L26: ='Walmart (L)'!E26 -> 0.160625
A27: Chicken breast | B27: 2 breasts | C27: ='Wegmans (F)'!E27 -> 6.43 | D27: ='Trader Joes (F)'!E27 -> 7.49 | E27: ='Mclanahans (N)'!E27 -> 4.43 | F27: ='Weis (N)'!E27 -> 3.99 | G27: ='Target D (T)'!E27 -> 2.495 | H27: ='Giant (T)'!E27 -> 2.495 | I27: ='Sams Club (N)'!E27 -> 4.14 | J27: 6.385 | K27: ='Aldi (L)'!E27 -> 5.79 | L27: ='Walmart (L)'!E27 -> 5.88
A28: Black beans | B28: 1 can | C28: ='Wegmans (F)'!E28 -> 0 | D28: ='Trader Joes (F)'!E28 -> 0.99 | E28: ='Mclanahans (N)'!E28 -> 1.65 | F28: ='Weis (N)'!E28 -> 0.79 | G28: ='Target D (T)'!E28 -> 0.99 | H28: ='Giant (T)'!E28 -> 0.89 | I28: ='Sams Club (N)'!E28 -> 0.99666667 | J28: 1.59 | K28: ='Aldi (L)'!E28 -> 0.95 | L28: ='Walmart (L)'!E28 -> 0.86
A29: Shredded cheddar cheese | B29: 1/4 cup | C29: ='Wegmans (F)'!E29 -> 0 | D29: ='Trader Joes (F)'!E29 -> 4.29 | E29: ='Mclanahans (N)'!E29 -> 0.67 | F29: ='Weis (N)'!E29 -> 0.6 | G29: ='Target D (T)'!E29 -> 0.24875 | H29: ='Giant (T)'!E29 -> 0.24875 | I29: ='Sams Club (N)'!E29 -> 2.735 | J29: 1.99 | K29: ='Aldi (L)'!E29 -> 2.65 | L29: ='Walmart (L)'!E29 -> 1.97
A30: Salt/Pepper | B30: 1 tsp | C30: ='Wegmans (F)'!E30 -> 0 | D30: ='Trader Joes (F)'!E30 -> 0.01 | E30: ='Mclanahans (N)'!E30 -> 0.1 | F30: ='Weis (N)'!E30 -> 0.1 | G30: ='Target D (T)'!E30 -> 0.22422535 | H30: ='Giant (T)'!E30 -> 0.056056338 | I30: ='Sams Club (N)'!E30 -> 0.0775 | J30: 0.146 | K30: ='Aldi (L)'!E30 -> 0.096910569 | L30: ='Walmart (L)'!E30 -> 0.01
A31: Olive oil (sub with vegetable) | B31: 1 Tbs | C31: ='Wegmans (F)'!E31 -> 0 | D31: ='Trader Joes (F)'!E31 -> 0.3 | E31: ='Mclanahans (N)'!E31 -> 0.52 | F31: ='Weis (N)'!E31 -> 0.35 | G31: ='Target D (T)'!E31 -> 0.19363636 | H31: ='Giant (T)'!E31 -> 0.21181818 | I31: ='Sams Club (N)'!E31 -> 0.096005917 | J31: 0.18905325 | K31: ='Aldi (L)'!E31 -> 0.18382353 | L31: ='Walmart (L)'!E31 -> 0.17470588
A32: Totals/Meal Total | C32: ='Wegmans (F)'!E32 -> 9.08 | D32: ='Trader Joes (F)'!E32 -> 15.07 | E32: ='Mclanahans (N)'!E32 -> 11.05 | F32: ='Weis (N)'!E32 -> 8.64 | G32: ='Target D (T)'!E32 -> 6.2569242 | H32: ='Giant (T)'!E32 -> 4.004437 | I32: ='Sams Club (N)'!E32 -> 9.3344434 | J32: ='Target Up (N)'!E32 -> 15.099116 | K32: ='Aldi (L)'!E32 -> 12.123547 | L32: ='Walmart (L)'!E32 -> 11.175331
A33: Recipe Reference:
A35: Taco Soup - Liliana | Q35: 6
A36: Ground Beef | B36: 1lb | C36: ='Wegmans (F)'!E36 -> 0 | D36: ='Trader Joes (F)'!E36 -> 6.49 | E36: ='Mclanahans (N)'!E36 -> 10.59 | F36: ='Weis (N)'!E36 -> 7.29 | G36: ='Target D (T)'!E36 -> 6.19 | H36: ='Giant (T)'!E36 -> 6.89 | I36: ='Sams Club (N)'!E36 -> 5.96 | J36: ='Target Up (N)'!E36 -> 7.99 | K36: ='Aldi (L)'!E36 -> 6.95 | L36: ='Walmart (L)'!E36 -> 6.26
A37: Onion (yellow?) | B37: 1 | C37: ='Wegmans (F)'!E37 -> 0 | D37: ='Trader Joes (F)'!E37 -> 1.19 | E37: ='Mclanahans (N)'!E37 -> 0.99 | F37: ='Weis (N)'!E37 -> 0.5 | G37: ='Target D (T)'!E37 -> 0.99 | H37: ='Giant (T)'!E37 -> 0.54 | I37: ='Sams Club (N)'!E37 -> N/A | J37: ='Target Up (N)'!E37 -> 0.89 | K37: ='Aldi (L)'!E37 -> 0.438 | L37: ='Walmart (L)'!E37 -> 0.78
A38: Diced tomatos | B38: 1 can | C38: ='Wegmans (F)'!E38 -> 0 | D38: ='Trader Joes (F)'!E38 -> 0 | E38: ='Mclanahans (N)'!E38 -> 1.95 | F38: ='Weis (N)'!E38 -> 0.99 | G38: ='Target D (T)'!E38 -> 0.99 | H38: ='Giant (T)'!E38 -> 1 | I38: ='Sams Club (N)'!E38 -> 1.235 | J38: ='Target Up (N)'!E38 -> 3.79 | K38: ='Aldi (L)'!E38 -> 0.99 | L38: ='Walmart (L)'!E38 -> 0.96
A39: Taco seasoning | B39: 1 packet | C39: ='Wegmans (F)'!E39 -> 0 | D39: ='Trader Joes (F)'!E39 -> 1.19 | E39: ='Mclanahans (N)'!E39 -> 1.39 | F39: ='Weis (N)'!E39 -> 0.59 | G39: ='Target D (T)'!E39 -> 0.99 | H39: ='Giant (T)'!E39 -> 0.79 | I39: ='Sams Club (N)'!E39 -> 0.698 | J39: ='Target Up (N)'!E39 -> 0.99 | K39: ='Aldi (L)'!E39 -> 0.55 | L39: ='Walmart (L)'!E39 -> 0.97
A40: Kidney beans | B40: 1 can | C40: ='Wegmans (F)'!E40 -> 0 | D40: ='Trader Joes (F)'!E40 -> 1.19 | E40: ='Mclanahans (N)'!E40 -> 1.55 | F40: ='Weis (N)'!E40 -> 0.79 | G40: ='Target D (T)'!E40 -> 1.19 | H40: ='Giant (T)'!E40 -> 0.89 | I40: ='Sams Club (N)'!E40 -> 0.99666667 | J40: ='Target Up (N)'!E40 -> 1.49 | K40: ='Aldi (L)'!E40 -> 0.95 | L40: ='Walmart (L)'!E40 -> 0.86
A41: Sweet corn | B41: 1 can | C41: ='Wegmans (F)'!E41 -> 0 | D41: ='Trader Joes (F)'!E41 -> 0.99 | E41: ='Mclanahans (N)'!E41 -> 1.79 | F41: ='Weis (N)'!E41 -> 0.89 | G41: ='Target D (T)'!E41 -> 0.59 | H41: ='Giant (T)'!E41 -> 0.75 | I41: ='Sams Club (N)'!E41 -> 1.0525 | J41: ='Target Up (N)'!E41 -> 0.99 | K41: ='Aldi (L)'!E41 -> 0.85 | L41: ='Walmart (L)'!E41 -> 0.76
A42: Salt/Pepper | B42: A pinch | C42: ='Wegmans (F)'!E42 -> 0 | D42: ='Trader Joes (F)'!E42 -> 0.01 | E42: ='Mclanahans (N)'!E42 -> 0.1 | F42: ='Weis (N)'!E42 -> 0.1 | G42: ='Target D (T)'!E42 -> 0.056056338 | H42: ='Giant (T)'!E42 -> 0.056056338 | I42: ='Sams Club (N)'!E42 -> 0.0775 | J42: ='Target Up (N)'!E42 -> 0.146 | K42: ='Aldi (L)'!E42 -> 0.096910569 | L42: ='Walmart (L)'!E42 -> 0.01
A43: Shredded cheddar cheese | B43: 1.5 cup bag | C43: ='Wegmans (F)'!E43 -> 0 | D43: ='Trader Joes (F)'!E43 -> 4.29 | E43: ='Mclanahans (N)'!E43 -> 4.04 | F43: ='Weis (N)'!E43 -> 2.84 | G43: ='Target D (T)'!E43 -> 1.3266667 | H43: ='Giant (T)'!E43 -> 1.4925 | I43: ='Sams Club (N)'!E43 -> 2.735 | J43: ='Target Up (N)'!E43 -> 2.985 | K43: ='Aldi (L)'!E43 -> 5.3 | L43: ='Walmart (L)'!E43 -> 1.97
A44: Fritos | B44: half bag | C44: ='Wegmans (F)'!E44 -> 0 | D44: ='Trader Joes (F)'!E44 -> 0 | E44: ='Mclanahans (N)'!E44 -> 1.99 | F44: ='Weis (N)'!E44 -> 2.49 | G44: ='Target D (T)'!E44 -> 2.345 | H44: ='Giant (T)'!E44 -> 2.745 | I44: ='Sams Club (N)'!E44 -> 2.24 | J44: ='Target Up (N)'!E44 -> 2.345 | K44: ='Aldi (L)'!E44 -> 0.14538462 | L44: ='Walmart (L)'!E44 -> 1.985
...

Sheet Wegmans (F)
A1: Ingredient | B1: Quantity (Recipe) | C1: Price | D1: Quantity (Store) | E1: Per Recipe | F1: Link
A3: Baked Feta Pasta - Taryn | O3: 6
A4: Baby Spinach | B4: 1 bag | C4: 3.29 | D4: 5 oz | E4: 3.29 | F4: https://www.wegmans.com/shop/search?query=baby%20spinach
A5: Cherry Tomatoes | B5: 1 container | C5: 6.49 | D5: 12 oz | E5: 6.49 | F5: https://www.wegmans.com/shop/search?query=cherry%20tomatoes
A6: Feta Block | B6: 1 block | C6: 4.99 | D6: 8 oz | E6: 4.99 | F6: https://images.wegmans.com/is/image/wegmanscsprod/970171_PrimaryImage?v=ec6443badbcab4e697377e7c75fc0e151649d13a
A7: Olive oil | B7: 2 tbsp | C7: 9.79 | D7: 33.8 oz | E7: 0.29 | F7: https://www.wegmans.com/shop/search?query=olive%20oil
A8: Salt/Pepper | B8: generous amount | C8: 2.49 | D8: 5.25 oz | E8: 0.01 | F8: https://www.wegmans.com/shop/search?query=salt%20pepper
A9: Minced garlic | B9: 2 tbsp | C9: 3.49 | D9: 8 oz | E9: 0.44 | F9: https://www.wegmans.com/shop/search?query=minced%20garlic
A10: Pasta | B10: 8 oz | C10: 0.99 | D10: 16 0z | E10: 0.5 | F10: https://images.wegmans.com/is/image/wegmanscsprod/48986_PrimaryImage?v=13.1
A11: Totals | C11: =SUM(C4:C10) -> 31.53 | E11: =SUM(E4:E10) -> 16.01
A12: Recipe Reference: https://thespicegirlkitchen.com/creamy-salmon-pasta/
A14: Overnight Oats - Taryn | O14: 1
A15: Old fashioned oats | B15: 1/4 cup | C15: 4.19 | D15: 42 oz | E15: 0.07 | F15: https://www.wegmans.com/shop/search?query=old%20fashioned%20oats
A16: Greek yogurt | B16: 1/4 cup | C16: 3.99 | D16: 32 oz | E16: 0.09 | F16: https://www.wegmans.com/shop/search?query=greek%20yogurt
A17: Milk (2%?) | B17: 1/3 cup | C17: 2.51 | D17: 64 oz | E17: 0.1 | F17: https://www.wegmans.com/shop/search?query=milk
A18: Chia Seeds | B18: 2 tsp | C18: 9.99 | D18: 32 oz | E18: 0.1 | F18: https://www.wegmans.com/shop/search?query=chia%20seeds
A19: Strawberries | B19: 1/4 cup | C19: 3.99 | D19: 16 oz | E19: 0.5 | F19: https://www.wegmans.com/shop/search?query=strawberries
A20: Honey | B20: 2 tsp | C20: 4.79 | D20: 16 oz | E20: 10 | F20: https://www.wegmans.com/shop/search?query=honey
A21: Totals | C21: =SUM(C15:C20) -> 29.46 | E21: =SUM(E15:E20) -> 10.86
A22: Recipe reference: https://www.allrecipes.com/recipe/244251/no-cook-overnight-oatmeal/
A24: Quesidilla - Liliana | O24: 4
A25: Tortilla (Large?) | B25: 8 | C25: 2.49 | D25: 8 | E25: 2.49 | F25: https://www.wegmans.com/shop/search?query=tortilla
A26: Butter | B26: 1 tbs | C26: 4.99 | D26: 16 oz | E26: 0.16 | F26: https://www.wegmans.com/shop/search?query=butter
A27: Chicken breast | B27: 2 breasts | C27: 9.65 | D27: 1.5 lbs | E27: 6.43
A28: Black beans | B28: 1 can
A29: Shredded cheddar cheese | B29: 1 bag
A30: Salt/Pepper | B30: 1 tsp | F30: Repeat Item
A31: Olive oil (sub with vegetable) | B31: 1 Tbs | F31: Repeat Item
A32: Totals | C32: =SUM(C25:C31) -> 17.13 | E32: =SUM(E25:E31) -> 9.08
A33: Recipe Reference:
A35: Taco Soup - Liliana | O35: 6
A36: Ground Beef | B36: 1lb
A37: Onion (yellow?) | B37: 1
A38: Diced tomatos | B38: 1 can
A39: Taco seasoning | B39: 1 packet
A40: Kindey beans | B40: 1 can
A41: Sweet corn | B41: 1 can
A42: Salt/Pepper | B42: A pinch | F42: Repeat Item
A43: Shredded cheddar cheese | B43: 1.5 cup bag
A44: Fritos | B44: half bag
...

Sheet Trader Joes (F)
A1: Ingredient | B1: Quantity (Recipe) | C1: Price | D1: Quantity (Store) | E1: Per Recipe | F1: Link
A3: Baked Feta Pasta - Taryn | O3: 6
A4: Baby Spinach | B4: 1 bag | C4: 2.29 | D4: 6 oz | E4: 2.29 | F4: https://www.traderjoes.com/home/products/category/veggies-119
A5: Cherry Tomatoes | B5: 1 container | C5: 4.99 | D5: 12 oz | E5: 4.99 | F5: https://www.traderjoes.com/home/products/pdp/cherry-tomatoes-on-the-vine-070500
A6: Feta Block | B6: 1 block | C6: 3.79 | D6: 8 oz | E6: 3.79 | F6: https://www.traderjoes.com/home/products/pdp/feta-cheese-079858
A7: Olive oil | B7: 2 tbsp | C7: 9.99 | D7: 33.8 oz | E7: 0.3 | F7: https://www.traderjoes.com/home/products/pdp/imported-olive-oil-packed-in-italy-001437
A8: Salt/Pepper | B8: generous amount | C8: 1.69 | D8: 17.6 Oz | E8: 0.01 | F8: https://www.traderjoes.com/home/products/pdp/fine-grain-pink-salt-076300, https://www.traderjoes.com/home/products/pdp/organic-ground-black-pepper-068491
A9: Minced garlic | B9: 2 tbsp
A10: Pasta | B10: 8 oz | C10: 1.99 | D10: 16 oz | E10: 1 | F10: https://www.traderjoes.com/home/products/pdp/organic-fusilli-corti-bucati-pasta-072525
A11: Totals | C11: =SUM(C4:C10) -> 24.74 | E11: =SUM(E4:E10) -> 12.38
A12: Recipe Reference: https://thespicegirlkitchen.com/creamy-salmon-pasta/
A14: Overnight Oats - Taryn | O14: 1
A15: Old fashioned oats | B15: 1/4 cup | C15: 2.99 | D15: 18 oz | E15: 0.33 | F15: https://www.traderjoes.com/home/products/pdp/oven-toasted-old-fashioned-organic-oats-004856
A16: Greek yogurt | B16: 1/4 cup | C16: 2.99 | D16: 16 oz | E16: 0.37 | F16: https://www.traderjoes.com/home/products/pdp/greek-nonfat-yogurt-plain-086450
A17: Milk (2%?) | B17: 1/3 cup | C17: 5.99 | D17: 64 oz
A18: Chia Seeds | B18: 2 tsp
A19: Strawberries | B19: 1/4 cup | C19: 6.99 | D19: 32 oz | E19: 0.07 | F19: https://www.traderjoes.com/home/products/pdp/strawberries-2-lb-078515
A20: Honey | B20: 2 tsp
A21: Totals | C21: =SUM(C15:C20) -> 18.96 | E21: =SUM(E15:E20) -> 0.77
A22: Recipe reference: https://www.allrecipes.com/recipe/244251/no-cook-overnight-oatmeal/
A24: Quesidilla - Liliana | O24: 4
A25: Tortilla (Large?) | B25: 8 | C25: 2.99 | D25: 12 tortilla | E25: 1.99 | F25: https://www.traderjoes.com/home/products/pdp/sonora-style-flour-tortillas-077519
A26: Butter | B26: 1 tbs
A27: Chicken breast | B27: 2 breasts | C27: 7.49 | D27: 1lb | E27: 7.49 | F27: https://www.traderjoes.com/home/products/pdp/organic-free-range-boneless-skinless-chicken-breasts-063550
A28: Black beans | B28: 1 can | C28: 0.99 | D28: 5 oz | E28: 0.99 | F28: https://www.traderjoes.com/home/products/pdp/black-beans-009636
A29: Shredded cheddar cheese | B29: 1 bag | C29: 4.29 | D29: 12 oz | E29: 4.29 | F29: https://www.traderjoes.com/home/products/pdp/shredded-3-cheese-blend-016541
A30: Salt/Pepper | B30: 1 tsp | C30: 1.69 | D30: 17.6 Oz | E30: 0.01 | F30: https://www.traderjoes.com/home/products/pdp/fine-grain-pink-salt-076300, https://www.traderjoes.com/home/products/pdp/organic-ground-black-pepper-068491
A31: Olive oil (sub with vegetable) | B31: 1 Tbs | C31: 9.99 | D31: 33.8 oz | E31: 0.3 | F31: https://www.traderjoes.com/home/products/pdp/imported-olive-oil-packed-in-italy-001437
A32: Totals | C32: =SUM(C25:C31) -> 27.44 | E32: =SUM(E25:E31) -> 15.07
A33: Recipe Reference:
A35: Taco Soup - Liliana | O35: 6
A36: Ground Beef | B36: 1lb | C36: 6.49 | D36: 16 oz | E36: 6.49 | F36: https://www.traderjoes.com/home/products/pdp/ground-beef-80-lean-20-fat-091082
A37: Onion (yellow?) | B37: 1 | C37: 1.19 | D37: 1 onion | E37: 1.19 | F37: https://www.traderjoes.com/home/products/pdp/jumbo-yellow-onions-095520
A38: Diced tomatos | B38: 1 can
A39: Taco seasoning | B39: 1 packet | C39: 1.19 | D39: 1 packet | E39: 1.19 | F39: https://www.traderjoes.com/home/products/pdp/taco-seasoning-mix-093089
A40: Kindey beans | B40: 1 can | C40: 1.19 | D40: 15.5 oz | E40: 1.19 | F40: https://www.traderjoes.com/home/products/pdp/organic-kidney-beans-050264
A41: Sweet corn | B41: 1 can | C41: 0.99 | D41: 15 oz | E41: 0.99 | F41: https://www.traderjoes.com/home/products/pdp/whole-kernel-corn-001605
A42: Salt/Pepper | B42: A pinch | C42: 1.69 | D42: 17.6 Oz | E42: 0.01 | F42: https://www.traderjoes.com/home/products/pdp/fine-grain-pink-salt-076300, https://www.traderjoes.com/home/products/pdp/organic-ground-black-pepper-068491
A43: Shredded cheddar cheese | B43: 1.5 cup bag | C43: 4.29 | D43: 12 oz | E43: 4.29 | F43: https://www.traderjoes.com/home/products/pdp/shredded-3-cheese-blend-016541
A44: Fritos | B44: half bag
...

Sheet Mclanahans (N)
A1: Ingredient | B1: Quantity (Recipe) | C1: Price | D1: Quantity (Store) | E1: Per Recipe | F1: Link
A3: Baked Feta Pasta - Taryn | O3: 6
A4: Baby Spinach | B4: 1 bag | C4: 2.99 | D4: 5oz bag | E4: 2.99 | F4: NA
A5: Cherry Tomatoes | B5: 1 container | C5: 2.89 | D5: 8oz container | E5: 2.89 | F5: NA
A6: Feta Block | B6: 1 block | C6: NA | D6: NA | E6: NA | F6: NA
A7: Olive oil | B7: 2 tbsp | C7: 8.85 | D7: 17 fl oz | E7: 0.52 | F7: NA
A8: Salt/Pepper | B8: generous amount | C8: 5.89 | D8: 3.4 oz shakers | E8: 0.1 | F8: NA
A9: Minced garlic | B9: 2 tbsp | C9: 2.89 | D9: 6oz jar | E9: 0.49 | F9: NA
A10: Pasta | B10: 8 oz | C10: 2.55 | D10: 16oz package | E10: 1.28 | F10: NA
A11: Totals | C11: =SUM(C4:C10) -> 26.06 | E11: =SUM(E4:E10) -> 8.27 | F11: NA
A12: Recipe Reference: https://thespicegirlkitchen.com/creamy-salmon-pasta/
A14: Overnight Oats - Taryn | O14: 1
A15: Old fashioned oats | B15: 1/4 cup | C15: NA | D15: NA | E15: NA
A16: Greek yogurt | B16: 1/4 cup | C16: 8.99 | D16: 32 oz container | E16: 0.56 | F16: NA
A17: Milk (2%?) | B17: 1/3 cup | C17: 4.79 | D17: 1 gallon | E17: 0.1 | F17: NA
A18: Chia Seeds | B18: 2 tsp | C18: 4.5 | D18: 8 oz bag | E18: 0.18 | F18: NA
A19: Strawberries | B19: 1/4 cup | C19: 4.5 | D19: 1 lb container | E19: 0.42 | F19: NA
A20: Honey | B20: 2 tsp | C20: 3.69 | D20: 12 oz container | E20: 0.1 | F20: NA
A21: Totals | C21: =SUM(C15:C20) -> 26.47 | E21: =SUM(E15:E20) -> 1.36
A22: Recipe reference: https://www.allrecipes.com/recipe/244251/no-cook-overnight-oatmeal/
A24: Quesidilla - Liliana | O24: 4
A25: Tortilla (Large?) | B25: 8 | C25: 3.49 | D25: 8 pack | E25: 3.49 | F25: NA
A26: Butter | B26: 1 tbs | C26: 5.75 | D26: 15 oz container | E26: 0.19 | F26: NA
A27: Chicken breast | B27: 2 breasts | C27: 12.39 | D27: 3.5 lbs | E27: 4.43 | F27: NA
A28: Black beans | B28: 1 can | C28: 1.65 | D28: 15 oz can | E28: 1.65 | F28: NA
A29: Shredded cheddar cheese | B29: 1/4 cup | C29: 5.39 | D29: 8 oz bag | E29: 0.67 | F29: NA
A30: Salt/Pepper | B30: 1 tsp | C30: 5.89 | D30: 3.4 oz shakers | E30: 0.1 | F30: Repeat Item
A31: Olive oil (sub with vegetable) | B31: 1 Tbs | C31: 8.85 | D31: 17 fl oz | E31: 0.52 | F31: Repeat Item
A32: Totals | C32: =SUM(C25:C31) -> 43.41 | E32: =SUM(E25:E31) -> 11.05
A33: Recipe Reference:
A35: Taco Soup - Liliana | O35: 6
A36: Ground Beef | B36: 1lb | C36: 10.59 | D36: 1 lb container | E36: 10.59 | F36: NA
A37: Onion (yellow?) | B37: 1 | C37: 0.99 | D37: 1 individual | E37: 0.99 | F37: NA
A38: Diced tomatos | B38: 1 can | C38: 1.95 | D38: 15 oz can | E38: 1.95 | F38: NA
A39: Taco seasoning | B39: 1 packet | C39: 1.39 | D39: 1 oz package | E39: 1.39 | F39: NA
A40: Kindey beans | B40: 1 can | C40: 1.55 | D40: 1 can | E40: 1.55 | F40: NA
A41: Sweet corn | B41: 1 can | C41: 1.79 | D41: 1 can | E41: 1.79 | F41: NA
A42: Salt/Pepper | B42: A pinch | C42: 5.89 | D42: 3.4 oz shakers | E42: 0.1 | F42: Repeat Item
A43: Shredded cheddar cheese | B43: 1.5 cup bag | C43: 5.39 | D43: 8 oz bag | E43: 4.04 | F43: NA
A44: Fritos | B44: half bag | C44: 3.99 | D44: 1 bag | E44: 1.99 | F44: NA
...

Sheet Weis (N)
A1: Ingredient | B1: Quantity (Recipe) | C1: Price | D1: Quantity (Store) | E1: Per Recipe | F1: Link
A3: Baked Feta Pasta - Taryn | O3: 6
A4: Baby Spinach | B4: 1 bag | C4: 3.79 | D4: 5 oz bag | E4: 1.52 | F4: Bag of Baby Spinach - Weis
A5: Cherry Tomatoes | B5: 1 container | C5: 4.99 | D5: 12 oz container | E5: 2.49 | F5: Cherry Tomatoes - Weis
A6: Feta Block | B6: 1 block | C6: 4.99 | D6: block | E6: 4.99 | F6: Feta Block - Weis
A7: Olive oil | B7: 2 tbsp | C7: 10.99 | D7: 16 fl oz bottle | E7: 0.69 | F7: Olive Oil Bottle - Weis
A8: Salt/Pepper | B8: generous amount | C8: 2.99 | D8: 5.25 oz shakers | E8: 0.1 | F8: Salt/Pepper Shakers - Weis
A9: Minced garlic | B9: 2 tbsp | C9: 2.99 | D9: 4.5 oz | E9: 0.32 | F9: Minced Garlic - Weis
A10: Pasta | B10: 8 oz | C10: 1.25 | D10: 12 oz container | E10: 0.83 | F10: Farfalle Pasta - Weis
A11: Totals | C11: =SUM(C4:C10) -> 31.99 | E11: =SUM(E4:E10) -> 10.94
A12: Recipe Reference: https://thespicegirlkitchen.com/creamy-salmon-pasta/
A14: Overnight Oats - Taryn | O14: 1
A15: Old fashioned oats | B15: 1/4 cup | C15: 2.59 | D15: 18 oz container | E15: 0.12 | F15: Old Fashioned Oats - Weis
A16: Greek yogurt | B16: 1/4 cup | C16: 5.99 | D16: 32 oz container | E16: 0.37 | F16: Vanilla Greek Yogurt - Weis
A17: Milk (2%?) | B17: 1/3 cup | C17: 1.79 | D17: 32 fl oz carton | E17: 0.15 | F17: 2% Milk Quart - Weis
A18: Chia Seeds | B18: 2 tsp | C18: 6.29 | D18: 14 oz package | E18: 0.14 | F18: Chia Seeds - Weis
A19: Strawberries | B19: 1/4 cup | C19: 4.99 | D19: 1 lb package | E19: 0.39 | F19: 1 lb Container of Strawberries - Weis
A20: Honey | B20: 2 tsp | C20: 5.99 | D20: 12 oz container | E20: 0.21 | F20: Bear Shaped Honey Container - Weis
A21: Totals | C21: =SUM(C15:C20) -> 27.64 | E21: =SUM(E15:E20) -> 1.38
A22: Recipe reference: https://www.allrecipes.com/recipe/244251/no-cook-overnight-oatmeal/
A24: Quesidilla - Liliana | O24: 4
A25: Tortilla (Large?) | B25: 8 | C25: 2.69 | D25: 8 count pack | E25: 2.69 | F25: Tortillas - Weis
A26: Butter | B26: 1 tbs | C26: 1.99 | D26: 8 ounce pack | E26: 0.12 | F26: Butter Sticks - Weis
A27: Chicken breast | B27: 2 breasts | C27: 7.99 | D27: 1.5 lb container | E27: 3.99 | F27: Chicken Breasts - Weis
A28: Black beans | B28: 1 can | C28: 0.79 | D28: 16 oz container | E28: 0.79 | F28: Black Beans - Weis
A29: Shredded cheddar cheese | B29: 1 bag | C29: 2.39 | D29: 8 oz bag | E29: 0.6 | F29: Shredded Cheese - Weis
A30: Salt/Pepper | B30: 1 tsp | C30: 2.99 | D30: 5.25 oz shakers | E30: 0.1 | F30: Repeat Item
A31: Olive oil (sub with vegetable) | B31: 1 Tbs | C31: 10.99 | D31: 16 fl oz bottle | E31: 0.35 | F31: Repeat Item
A32: Totals | C32: =SUM(C25:C31) -> 29.83 | E32: =SUM(E25:E31) -> 8.64
A33: Recipe Reference:
A35: Taco Soup - Liliana | O35: 6
A36: Ground Beef | B36: 1lb | C36: 7.29 | D36: 1 lb container | E36: 7.29 | F36: Ground Beef - Weis
A37: Onion (yellow?) | B37: 1 | C37: 2.99 | D37: 3lb bag | E37: 0.5 | F37: Yellow Onions - Weis
A38: Diced tomatos | B38: 1 can | C38: 0.99 | D38: 1 can | E38: 0.99 | F38: Tomatoes - Weis
A39: Taco seasoning | B39: 1 packet | C39: 0.59 | D39: 1 packet | E39: 0.59 | F39: Taco Seasoning - Weis
A40: Kindey beans | B40: 1 can | C40: 0.79 | D40: 1 can | E40: 0.79 | F40: Kidney Beans
A41: Sweet corn | B41: 1 can | C41: 0.89 | D41: 1 can | E41: 0.89 | F41: Sweet Corn - Weis
A42: Salt/Pepper | B42: A pinch | C42: 2.99 | D42: 5.25 oz shakers | E42: 0.1 | F42: Repeat Item
A43: Shredded cheddar cheese | B43: 1.5 cup bag | C43: 3.79 | D43: 2 cup bag | E43: 2.84 | F43: Shredded Cheese - Weis
A44: Fritos | B44: half bag | C44: 4.99 | D44: 1 bag | E44: 2.49 | F44: Fritos - Weis
...

Sheet Target D (T)
A1: Ingredient | B1: Quantity (Recipe) | C1: Price | D1: Quantity (Store) | E1: Per Recipe | F1: Link
A3: Baked Feta Pasta - Taryn | O3: 6
A4: Baby Spinach | B4: 1 bag | C4: 2.19 | D4: 5 oz | E4: 2.19 | F4: https://www.target.com/p/baby-spinach-5oz-good-38-gather-8482/-/A-54555524#lnk=sametab
A5: Cherry Tomatoes | B5: 1 container | C5: 2.59 | D5: 10 oz | E5: 2.59 | F5: Fresh Premium Cherry Tomatoes - 10oz - Good & Gather™ (Packaging May Vary) : Target
A6: Feta Block | B6: 1 block | C6: 5.29 | D6: 8 oz | E6: 5.29 | F6: Feta Cheese Chunk - 8oz - Good & Gather™ : Target
A7: Olive oil | B7: 2 tbsp | C7: 6.39 | D7: 33 tbsp | E7: =6.39*(2/33) -> 0.38727273 | F7: Extra Virgin Olive Oil - 16.9oz - Good & Gather™ : Target
A8: Salt/Pepper | B8: generous amount | C8: 1.99 | D8: 71 of .25 tsp | E8: =1.99*(2/71) -> 0.056056338 | F8: Salt & Pepper Shakers - 5oz - Good & Gather™ : Target
A9: Minced garlic | B9: 2 tbsp | C9: 2.99 | D9: 9 tbsp | E9: =2.99*(2/9) -> 0.66444444 | F9: Spice World Organic Minced Garlic - 4.5oz : Target
A10: Pasta | B10: 8 oz | C10: 0.99 | D10: 16 oz | E10: =0.99/2 -> 0.495 | F10: Rotini - 16oz - Good & Gather™ : Target
A11: Totals | C11: =SUM(C4:C10) -> 22.43 | E11: =SUM(E4:E10) -> 11.672774
A12: Recipe Reference: https://thespicegirlkitchen.com/creamy-salmon-pasta/
A14: Overnight Oats - Taryn | O14: 1
A15: Old fashioned oats | B15: 1/4 cup | C15: 2.89 | D15: 13 of 1/2 cup | E15: =2.89*(1/13) -> 0.22230769 | F15: Old Fashioned Oats - 18oz - Good & Gather™ : Target
A16: Greek yogurt | B16: 1/4 cup | C16: 3.39 | D16: 15 of 1/5 cup | E16: =3.39*(1/15) -> 0.226 | F16: Greek Plain Nonfat Yogurt - 18g Protein 32oz - Good & Gather™ : Target
A17: Milk (2%?) | B17: 1/3 cup | C17: 4.89 | D17: 48 of 1/3 cup | E17: =4.89*(1/48) -> 0.101875 | F17: 2% Reduced Fat Milk - 1gal - Good & Gather™ : Target
A18: Chia Seeds | B18: 2 tsp | C18: NA | D18: NA | E18: NA | F18: None
A19: Strawberries | B19: 1/4 cup | C19: 3.99 | D19: 16 oz/2 cups | E19: =3.99*(1/8) -> 0.49875 | F19: Fresh Strawberries - 1lb : Target
A20: Honey | B20: 2 tsp | C20: 4.49 | D20: 48 tsp | E20: =4.49*(2/48) -> 0.18708333 | F20: Raw and Unfiltered North American Honey - 12oz - Good & Gather™ : Target
A21: Totals | C21: =SUM(C15:C20) -> 19.65 | E21: =SUM(E15:E20) -> 1.236016
A22: Recipe reference: https://www.allrecipes.com/recipe/244251/no-cook-overnight-oatmeal/
A24: Quesidilla - Liliana | O24: 4
A25: Tortilla (Large?) | B25: 8 | C25: 1.99 | D25: 8 | E25: 1.99 | F25: 8" Flour Tortillas - 10ct - Market Pantry™ : Target
A26: Butter | B26: 1 tbs | C26: 3.69 | D26: 32 tbsp | E26: =3.69*(1/32) -> 0.1153125 | F26: Unsalted Butter - 16oz/4ct - Good & Gather™ : Target
A27: Chicken breast | B27: 2 breasts | C27: 4.99 | D27: 1 lb | E27: =4.99/2 -> 2.495 | F27: Perdue Boneless & Skinless Antibiotic Free Chicken Breast - 1.3-2.4lbs - price per lb : Target
A28: Black beans | B28: 1 can | C28: 0.99 | D28: 1 can | E28: 0.99 | F28: Low Sodium Black Beans - 15.5oz - Good & Gather™ : Target
A29: Shredded cheddar cheese | B29: 1/4 cup | C29: 1.99 | D29: 8 o f1/4 cup | E29: =1.99*(1/8) -> 0.24875 | F29: Shredded Triple Cheddar Cheese - 8oz - Good & Gather™ : Target
A30: Salt/Pepper | B30: 1 tsp | C30: 1.99 | D30: 71 of .25 tsp | E30: =1.99*(8/71) -> 0.22422535 | F30: Repeat Item
A31: Olive oil (sub with vegetable) | B31: 1 Tbs | C31: 6.39 | D31: 33 tbsp | E31: =6.39*(1/33) -> 0.19363636 | F31: Repeat Item
A32: Totals | C32: =SUM(C26:C31) -> 20.04 | E32: =SUM(E25:E31) -> 6.2569242
A33: Recipe Reference:
A35: Taco Soup - Liliana | O35: 6
A36: Ground Beef | B36: 1lb | C36: 6.19 | D36: 1 lb | E36: 6.19 | F36: Fresh 73/27 Ground Beef - 1lb - Good & Gather™ : Target
A37: Onion (yellow?) | B37: 1 | C37: 0.99 | D37: 1 | E37: 0.99 | F37: Fresh Yellow Onion - each : Target
A38: Diced tomatos | B38: 1 can | C38: 0.99 | D38: 14.5 oz can | E38: 0.99 | F38: Diced Tomatoes - 14.5oz - Good & Gather™ : Target
A39: Taco seasoning | B39: 1 packet | C39: 0.99 | D39: 1 packet | E39: 0.99 | F39: Old El Paso Gluten Free Taco Seasoning Mix Original 1oz : Target
A40: Kindey beans | B40: 1 can | C40: 1.19 | D40: 15 oz can | E40: 1.19 | F40: Organic Low Sodium Dark Red Kidney Beans - 15oz - Good & Gather™ : Target
A41: Sweet corn | B41: 1 can | C41: 0.59 | D41: 15 oz can | E41: 0.59 | F41: Golden Sweet Whole Kernel Corn - 15.25oz - Good & Gather™ : Target
A42: Salt/Pepper | B42: A pinch | C42: 1.99 | D42: 71 of .25 tsp | E42: =1.99*(2/71) -> 0.056056338 | F42: Repeat Item
A43: Shredded cheddar cheese | B43: 1.5 cup | C43: 1.99 | D43: 8 o f1/4 cup | E43: =1.99*(2/3) -> 1.3266667 | F43: Repeat Item
A44: Fritos | B44: 1/2 bag | C44: 4.69 | D44: 9 oz bag | E44: =4.69*(1/2) -> 2.345 | F44: Fritos Original Corn Chips - 9.25oz : Target
...

Sheet Giant (T)
A1: Ingredient | B1: Quantity (Recipe) | C1: Price | D1: Quantity (Store) | E1: Per Recipe | F1: Link
A3: Baked Feta Pasta - Taryn | O3: 6
A4: Baby Spinach | B4: 1 bag | C4: 3.49 | D4: 6 oz bag | E4: 3.49 | F4: Our Brand Salad Basics Baby Spinach - 6 oz bag | GIANT
A5: Cherry Tomatoes | B5: 1 container | C5: 4.99 | D5: 10 oz package | E5: 4.99 | F5: NatureSweet Glorys Cherry Tomatoes - 10 oz pkg | GIANT
A6: Feta Block | B6: 1 block | C6: 3.99 | D6: block | E6: 3.99 | F6: Our Brand Feta Cheese Block - 6 oz pkg | GIANT
A7: Olive oil | B7: 2 tbsp | C7: 6.99 | D7: 33 tbsp | E7: =6.99*(2/33) -> 0.42363636 | F7: Our Brand Extra Virgin Olive Oil - 16.9 oz btl | GIANT
A8: Salt/Pepper | B8: generous amount | C8: 1.99 | D8: 71 of .25 tsp | E8: =1.99*(4/71) -> 0.11211268 | F8: Our Brand Salt & Pepper Pre-Filled Shakers - 1 set | GIANT
A9: Minced garlic | B9: 2 tbsp | C9: 2.49 | D9: 8 tbsp | E9: =2.49*(2/8) -> 0.6225 | F9: Nature's Promise Minced Garlic - 4.5 oz jar | GIANT
A10: Pasta | B10: 8 oz | C10: 1 | D10: 16 oz | E10: =1*(1/2) -> 0.5 | F10: Our Brand Linguine Pasta - 16 oz box | GIANT
A11: Totals | C11: =SUM(C4:C10) -> 24.94 | E11: =SUM(E4:E10) -> 14.128249
A12: Recipe Reference: https://thespicegirlkitchen.com/creamy-salmon-pasta/
A14: Overnight Oats - Taryn | O14: 1
A15: Old fashioned oats | B15: 1/4 cup | C15: 3.99 | D15: 60 of1/4 cups | E15: =3.99*(1/60) -> 0.0665 | F15: Our Brand Old Fashioned Rolled Oats - 42 oz can | GIANT
A16: Greek yogurt | B16: 1/4 cup | C16: 3.79 | D16: 15 of 1/4 cup | E16: =3.79*(1/15) -> 0.25266667 | F16: Our Brand Nonfat Plain Greek Yogurt - 32 oz tub | GIANT
A17: Milk (2%?) | B17: 1/3 cup | C17: 1.62 | D17: 12 of1/3 cup | E17: =1.62*(1/12) -> 0.135 | F17: Our Brand 2% Reduced Fat Milk - 1 quart | GIANT
A18: Chia Seeds | B18: 2 tsp | C18: 5.39 | D18: 45 tbsp | E18: =(2/45)*5.39 -> 0.23955556 | F18: Nature's Promise Organic Whole Black Chia Seeds - 16 oz pkg | GIANT
A19: Strawberries | B19: 1/4 cup | C19: 4.99 | D19: 16 oz/2 cups | E19: =4.99*(1/8) -> 0.62375 | F19: Strawberries - 16 oz pkg | GIANT
A20: Honey | B20: 2 tsp | C20: 3.69 | D20: 48 tsp | E20: =3.69*(2/48) -> 0.15375 | F20: Our Brand U.S. Grade A Wildflower Honey - 12 oz sqz | GIANT
A21: Totals | C21: =SUM(C15:C20) -> 23.47 | E21: =SUM(E15:E20) -> 1.4712222
A22: Recipe reference: https://www.allrecipes.com/recipe/244251/no-cook-overnight-oatmeal/
A24: Quesidilla - Liliana | O24: 4
A25: Tortilla (Large?) | B25: 8 | C25: 2.99 | D25: 8 ct | E25: 2.99 | F25: CHI-CHI'S Burrito Style Flour Tortillas 10 Inch - 8 ct - 17 oz pkg | GIANT
A26: Butter | B26: 1 tbs | C26: 3.29 | D26: 32 tbs | E26: =3.29*(1/32) -> 0.1028125 | F26: Our Brand Unsalted Sweet Cream Butter Sticks - 4 ct - 16 oz box | GIANT
A27: Chicken breast | B27: 2 breasts | C27: 4.99 | D27: 4 breasts | E27: =4.99*(2/4) -> 2.495 | F27: Our Brand 99% Fat Free Boneless Skinless Chicken Breast Cutlets - 4 ct - apx 1 lb | GIANT
A28: Black beans | B28: 1 can | C28: 0.89 | D28: 1 can | E28: 0.89 | F28: Our Brand Black Beans - 15.5 oz can | GIANT
A29: Shredded cheddar cheese | B29: 1/4 cup | C29: 1.99 | D29: 8 of 1/4 cup | E29: =1.99*(1/8) -> 0.24875 | F29: Our Brand Finely Shredded Sharp Cheddar Cheese - 8 oz bag | GIANT
A30: Salt/Pepper | B30: 1 tsp | C30: 1.99 | D30: 71 of .25 tsp | E30: =1.99*(2/71) -> 0.056056338 | F30: Repeat Item
A31: Olive oil (sub with vegetable) | B31: 1 Tbs | C31: 6.99 | D31: 33 tbsp | E31: =6.99*(1/33) -> 0.21181818 | F31: Repeat Item
A32: Totals | C32: =SUM(C26:C31) -> 20.14 | E32: =SUM(E26:E31) -> 4.004437
A33: Recipe Reference:
A35: Taco Soup - Liliana | O35: 6
A36: Ground Beef | B36: 1lb | C36: 6.89 | D36: 1 lb | E36: 6.89 | F36: Our Brand All Natural 80% Lean 20% Fat Ground Beef Fresh - apx 1.2 lb | GIANT
A37: Onion (yellow?) | B37: 1 | C37: 0.54 | D37: 1 | E37: 0.54 | F37: Yellow Onions - 1 ea | GIANT
A38: Diced tomatos | B38: 1 can | C38: 1 | D38: 14 oz can | E38: 1 | F38: Our Brand Diced Tomatoes - 14.5 oz can | GIANT
A39: Taco seasoning | B39: 1 packet | C39: 0.79 | D39: 1 pack | E39: 0.79 | F39: Our Brand Taco Seasoning Mix Packet - 1.25 oz pkt | GIANT
A40: Kindey beans | B40: 1 can | C40: 0.89 | D40: 15.5 oz can | E40: 0.89 | F40: Our Brand Light Red Kidney Beans - 15.5 oz can | GIANT
A41: Sweet corn | B41: 1 can | C41: 0.75 | D41: 15.2 oz can | E41: 0.75 | F41: Our Brand Whole Kernel Sweet Corn - 15.2 oz can | GIANT
A42: Salt/Pepper | B42: A pinch | C42: 1.99 | D42: 71 of .25 tsp | E42: =1.99*(2/71) -> 0.056056338 | F42: Repeat Item
A43: Shredded cheddar cheese | B43: 1.5 cup | C43: 1.99 | D43: 4 of 1/2 cup | E43: =1.99*(3/4) -> 1.4925 | F43: Our Brand Finely Shredded Sharp Cheddar Cheese - 8 oz bag | GIANT
A44: Fritos | B44: half bag | C44: 5.49 | D44: 288 chips | E44: =5.49*(1/2) -> 2.745 | F44: Fritos Corn Chips The Original - 9.25 oz bag | GIANT
...

Sheet Sams Club (N)
A1: Ingredient | B1: Quantity (Recipe) | C1: Price | D1: Quantity (Store) | E1: Per Recipe | F1: Link
A3: Baked Feta Pasta - Taryn | O3: 6
A4: Baby Spinach | B4: 1 bag | C4: 4.76 | D4: 16 oz. | E4: =(4.76) *(0.5) -> 2.38 | F4: baby spinach - Samsclub.com
A5: Cherry Tomatoes | B5: 1 container | C5: 6.65 | D5: 1.5lbs | E5: =6.65*(10/24) -> 2.7708333 | F5: Ombres Cherry Tomatoes On The Vine, 1.5 lbs. - Samsclub.com
A6: Feta Block | B6: 1 block | C6: 9.76 | D6: 32 oz. | E6: =9.76*(1/4) -> 2.44 | F6: President Feta Chunk Cheese, 32 oz. - Samsclub.com
A7: Olive oil | B7: 2 tbsp | C7: 12.98 | D7: 67.6 fl. oz. | E7: =12.98*(2/135.2) -> 0.19201183 | F7: Bertolli Extra Light Olive Oil, 67.6 fl. oz. - Samsclub.com
A8: Salt/Pepper | B8: generous amount | C8: 11.16 | D8: 96 oz. | E8: =11.16*(4/576) -> 0.0775 | F8: Morton Iodized Salt, 64 oz. - Samsclub.com
A9: Minced garlic | B9: 2 tbsp | C9: 5.68 | D9: 48 oz. | E9: =5.68*(2/96) -> 0.11833333 | F9: Member's Mark Minced Garlic, 48 oz. - Samsclub.com
A10: Pasta | B10: 8 oz | C10: 8.52 | D10: 6 lbs | E10: =8.52 *(8/96) -> 0.71 | F10: Barilla Pasta Rotini & Farfalle, Variety Pack, 1 lb., 6 pk. - Samsclub.com
A11: Totals | C11: =SUM(C4:C10) -> 59.51 | E11: =SUM(E4:E10) -> 8.6886785
A12: Recipe Reference: https://thespicegirlkitchen.com/creamy-salmon-pasta/
A14: Overnight Oats - Taryn | O14: 1
A15: Old fashioned oats | B15: 1/4 cup | C15: 7.98 | D15: 160 oz. | E15: =7.98*(0.25/20) -> 0.09975 | F15: Quaker Old Fashioned Oats, 160 oz. - Samsclub.com
A16: Greek yogurt | B16: 1/4 cup | C16: 4.97 | D16: 48 oz. | E16: =4.97*(0.25/6) -> 0.20708333 | F16: Member's Mark Nonfat Plain Greek Yogurt, 48 oz. - Samsclub.com
A17: Milk (2%?) | B17: 1/3 cup | C17: 3.94 | D17: 59 fl. oz. | E17: =3.94*((1/3)/7.375) -> 0.1780791 | F17: Members Mark 2% Ultra Filtered Milk, 59 fl. oz. - Samsclub.com
A18: Chia Seeds | B18: 2 tsp | C18: N/A | D18: N/A | E18: N/A | F18: N/A
A19: Strawberries | B19: 1/4 cup | C19: 6.97 | D19: 2 lbs. | E19: =6.97*(0.25/6) -> 0.29041667 | F19: Strawberries, 2 lbs. - Samsclub.com
A20: Honey | B20: 2 tsp | C20: 7.98 | D20: 48 oz. | E20: =7.98*(2/288) -> 0.055416667 | F20: Member’s Mark Wildflower Pure Premium Honey, 48 oz. - Samsclub.com
A21: Totals | C21: =SUM(C15:C20) -> 31.84 | E21: =SUM(E15:E20) -> 0.83074576
A22: Recipe reference: https://www.allrecipes.com/recipe/244251/no-cook-overnight-oatmeal/
A24: Quesidilla - Liliana | O24: 4
A25: Tortilla (Large?) | B25: 8 | C25: 3.67 | D25: 24 | E25: =3.67*(1/3) -> 1.2233333 | F25: https://www.samsclub.com/ip/La-Banderita-9-Homestyle-Soft-Taco-Flour-Tortillas-24-ct/13581873501?classType=REGULAR
A26: Butter | B26: 1 tbs | C26: 8.44 | D26: 128 tbsp | E26: =8.44*(1/128) -> 0.0659375 | F26: https://www.samsclub.com/ip/Member-s-Mark-Salted-Sweet-Cream-Butter-4-lbs/15365221245?classType=REGULAR&from=/search
A27: Chicken breast | B27: 2 breasts | C27: 16.56 | D27: 8 breasts | E27: =16.56*0.25 -> 4.14 | F27: https://www.samsclub.com/ip/Member-s-Mark-Boneless-and-Skinless-Chicken-Breast-priced-per-pound/18999111186?classType=REGULAR&from=/search
A28: Black beans | B28: 1 can | C28: 5.98 | D28: 6 cans | E28: =5.98/6 -> 0.99666667 | F28: https://www.samsclub.com/ip/Bush-s-Black-Beans-15-oz-6-pk/3940010881?classType=REGULAR
A29: Shredded cheddar cheese | B29: 1 bag | C29: 5.47 | D29: 2 lbs. | E29: =5.47/2 -> 2.735 | F29: https://www.samsclub.com/ip/Member-s-Mark-Mild-Cheddar-Shredded-Cheese-16-oz-2-pk/13771120208?classType=REGULAR&from=/search
A30: Salt/Pepper | B30: 1 tsp | C30: 11.16 | D30: 96 oz. | E30: =11.16*(4/576) -> 0.0775 | F30: Repeat Item
A31: Olive oil (sub with vegetable) | B31: 1 Tbs | C31: 12.98 | D31: 67.6 fl. oz. | E31: =12.98*(1/135.2) -> 0.096005917 | F31: Repeat Item
A32: Totals | C32: =SUM(C25:C31) -> 64.26 | E32: =SUM(E25:E31) -> 9.3344434
A33: Recipe Reference:
A35: Taco Soup - Liliana | O35: 6
A36: Ground Beef | B36: 1lb | C36: 19.07 | D36: 3 lbs | E36: 5.96 | F36: https://www.samsclub.com/ip/Member-s-Mark-93-7-Ground-Beef-priced-per-pound/13865573229?classType=REGULAR&from=/search
A37: Onion (yellow?) | B37: 1 | C37: N/A | D37: N/A | E37: N/A | F37: N/A
A38: Diced tomatos | B38: 1 can | C38: 9.88 | D38: 8 cans | E38: =9.88/8 -> 1.235 | F38: https://www.samsclub.com/ip/Hunt-s-Fire-Roasted-Diced-Tomatoes-14-5-oz-8-pk/16436162719?classType=REGULAR&from=/search
A39: Taco seasoning | B39: 1 packet | C39: 6.98 | D39: 10 packets | E39: =6.98/10 -> 0.698 | F39: https://www.samsclub.com/ip/Old-El-Paso-Original-Taco-Seasoning-1-oz-10-pk/13581873768?classType=REGULAR&from=/search
A40: Kindey beans | B40: 1 can | C40: 5.98 | D40: 6 cans | E40: =5.98/6 -> 0.99666667 | F40: https://www.samsclub.com/ip/Bush-s-Dark-Red-Kidney-Beans-16-oz-6-pk/3940010735?classType=REGULAR
A41: Sweet corn | B41: 1 can | C41: 8.42 | D41: 8 cans | E41: =8.42/8 -> 1.0525 | F41: https://www.samsclub.com/ip/Del-Monte-Golden-Sweet-Whole-Kernel-Corn-15-25-oz-8-pk/13596361849?classType=REGULAR
A42: Salt/Pepper | B42: A pinch | C42: 11.16 | D42: 96 oz. | E42: =11.16*(4/576) -> 0.0775 | F42: Repeat Item
A43: Shredded cheddar cheese | B43: 1.5 cup bag | C43: 5.47 | D43: 2 lbs. | E43: =5.47/2 -> 2.735 | F43: Repeat Item
A44: Fritos | B44: half bag | C44: 4.48 | D44: 18.125 oz. | E44: =4.48/2 -> 2.24 | F44: https://www.samsclub.com/ip/Fritos-The-Original-Corn-Chips-18-125-oz/13575872430?classType=REGULAR&from=/search
...

Sheet Target Up (N)
A1: Ingredient | B1: Quantity (Recipe) | C1: Price | D1: Quantity (Store) | E1: Per Recipe | F1: Link
A3: Baked Feta Pasta - Taryn | O3: 6
A4: Baby Spinach | B4: 1 bag | C4: 2.29 | D4: 1 bag | E4: 2.29 | F4: https://www.target.com/p/baby-spinach-5oz-good-38-gather-8482/-/A-54555524#lnk=sametab
A5: Cherry Tomatoes | B5: 1 container | C5: 2.49 | D5: 1 container | E5: 2.49 | F5: https://www.target.com/p/premium-cherry-tomatoes-10oz-good-38-gather-8482-packaging-may-vary/-/A-82667108#lnk=sametab
A6: Feta Block | B6: 1 block | C6: 5.29 | D6: 1 block | E6: 5.29 | F6: https://www.target.com/p/feta-cheese-good-gather/-/A-95143272?preselect=88076221#lnk=sametab
A7: Olive oil | B7: 2 tbsp | C7: 6.39 | D7: 33.8 tbsp | E7: =6.39*(2/33.8) -> 0.37810651 | F7: https://www.target.com/p/extra-virgin-olive-oil-good-gather/-/A-89409909?preselect=77643078#lnk=sametab
A8: Salt/Pepper | B8: generous amount | C8: 2.19 | D8: 5 oz | E8: =2.19/15 -> 0.146 | F8: https://www.target.com/p/salt-38-pepper-shakers-5oz-good-38-gather-8482/-/A-77588365#lnk=sametab
A9: Minced garlic | B9: 2 tbsp | C9: 3.79 | D9: 8 oz | E9: =3.79*(2/16) -> 0.47375 | F9: https://www.target.com/p/spice-world-minced-garlic-8oz/-/A-13556562#lnk=sametab
A10: Pasta | B10: 8 oz | C10: 0.99 | D10: 16 oz | E10: =0.99/2 -> 0.495 | F10: https://www.target.com/p/rotini-16oz-good-38-gather-8482/-/A-78779157#lnk=sametab
A11: Totals | C11: =SUM(C4:C10) -> 23.43 | E11: =SUM(E4:E10) -> 11.562857
A12: Recipe Reference: https://thespicegirlkitchen.com/creamy-salmon-pasta/
A14: Overnight Oats - Taryn | O14: 1
A15: Old fashioned oats | B15: 1/4 cup | C15: 4.89 | D15: 42 oz | E15: =4.89*(8/42) -> 0.93142857 | F15: https://www.target.com/p/quaker-oats-old-fashioned-oats-42oz/-/A-13331320#lnk=sametab
A16: Greek yogurt | B16: 1/4 cup | C16: 5.99 | D16: 32oz | E16: =5.99*(8/32) -> 1.4975 | F16: https://www.target.com/p/chobani-whole-milk-plain-greek-yogurt-32oz/-/A-15242876#lnk=sametab
A17: Milk (2%?) | B17: 1/3 cup | C17: 2.69 | D17: 8 cup | E17: =2.69*((1/3)/8) -> 0.11208333 | F17: https://www.target.com/p/milk-good-gather/-/A-94602358?preselect=12925351#lnk=sametab
A18: Chia Seeds | B18: 2 tsp | C18: 7.99 | D18: 8 oz | E18: =7.99*(2/48) -> 0.33291667 | F18: https://www.target.com/p/navitas-organics-vegan-chia-seeds-8oz/-/A-15317967#lnk=sametab
A19: Strawberries | B19: 1/4 cup | C19: 3.49 | D19: 3 cup | E19: =3.49*(0.25/3) -> 0.29083333 | F19: https://www.target.com/p/strawberries-1lb/-/A-13208903#lnk=sametab
A20: Honey | B20: 2 tsp | C20: 4.79 | D20: 12 oz | E20: =4.79*(2/72) -> 0.13305556 | F20: https://www.target.com/p/organic-raw-unfiltered-pure-honey-12oz-good-38-gather-8482/-/A-54436263#lnk=sametab
A21: Totals | C21: =SUM(C15:C20) -> 29.84 | E21: =SUM(E15:E20) -> 3.2978175
A22: Recipe reference: https://www.allrecipes.com/recipe/244251/no-cook-overnight-oatmeal/
A24: Quesidilla - Liliana | O24: 4
A25: Tortilla (Large?) | B25: 8 | C25: 4.69 | D25: 8 | E25: 4.69 | F25: https://www.target.com/p/mission-burrito-size-flour-tortillas-20oz-8ct/-/A-13101055#lnk=sametab
A26: Butter | B26: 1 tbs | C26: 3.49 | D26: 32 tbsp | E26: =3.49*(1/32) -> 0.1090625 | F26: https://www.target.com/p/butter-1lb-good-gather/-/A-94800768?preselect=80796339#lnk=sametab
A27: Chicken breast | B27: 2 breasts | C27: 12.77 | D27: 4 breasts | E27: =12.77/2 -> 6.385 | F27: https://www.target.com/p/boneless-skinless-chicken-breast-1-5-3-2lbs-price-per-lb-good-38-gather-8482/-/A-52205815#lnk=sametab
A28: Black beans | B28: 1 can | C28: 1.59 | D28: 1 can | E28: 1.59 | F28: https://www.target.com/p/goya-black-beans-15-5oz/-/A-14771988#lnk=sametab
A29: Shredded cheddar cheese | B29: 1 bag | C29: 1.99 | D29: 1 bag | E29: 1.99 | F29: https://www.target.com/p/shredded-cheese-good-gather/-/A-95161102?preselect=54337105#lnk=sametab
A30: Salt/Pepper | B30: 1 tsp | C30: 2.19 | D30: 5 oz | E30: =2.19/15 -> 0.146 | F30: Repeat Item
A31: Olive oil (sub with vegetable) | B31: 1 Tbs | C31: 6.39 | D31: 33.8 tbsp | E31: =6.39*(1/33.8) -> 0.18905325 | F31: Repeat Item
A32: Totals | C32: =SUM(C25:C31) -> 33.11 | E32: =SUM(E25:E31) -> 15.099116
A33: Recipe Reference:
A35: Taco Soup - Liliana | O35: 6
A36: Ground Beef | B36: 1lb | C36: 7.99 | D36: 1 lb | E36: 7.99 | F36: https://www.target.com/p/all-natural-93-7-ground-beef-good-gather/-/A-94935670?preselect=13288296#lnk=sametab
A37: Onion (yellow?) | B37: 1 | C37: 0.89 | D37: 1 | E37: 0.89 | F37: https://www.target.com/p/yellow-onion-each/-/A-13474244#lnk=sametab
A38: Diced tomatos | B38: 1 can | C38: 3.79 | D38: 1 can | E38: 3.79 | F38: https://www.target.com/p/muir-glen-organic-fire-roasted-diced-tomatoes/-/A-94669615?preselect=13032003#lnk=sametab
A39: Taco seasoning | B39: 1 packet | C39: 0.99 | D39: 1 packet | E39: 0.99 | F39: https://www.target.com/p/old-el-paso-taco-seasoning-mix-original-1oz/-/A-13015071#lnk=sametab
A40: Kindey beans | B40: 1 can | C40: 1.49 | D40: 1 can | E40: 1.49 | F40: https://www.target.com/p/bush-39-s-dark-red-kidney-beans-16oz/-/A-13593955#lnk=sametab
A41: Sweet corn | B41: 1 can | C41: 0.99 | D41: 1 can | E41: 0.99 | F41: https://www.target.com/p/golden-sweet-whole-kernel-corn-15-25oz-good-38-gather-8482/-/A-79466788#lnk=sametab
A42: Salt/Pepper | B42: A pinch | C42: 2.19 | D42: 5 oz | E42: =2.19/15 -> 0.146 | F42: Repeat Item
A43: Shredded cheddar cheese | B43: 1.5 cup bag | C43: =1.99*2 -> 3.98 | D43: 2 8 oz. bag | E43: =1.99*1.5 -> 2.985 | F43: Repeat Item
A44: Fritos | B44: half bag | C44: 4.69 | D44: 1 bag | E44: =4.69/2 -> 2.345 | F44: https://www.target.com/p/fritos-original-corn-chips-9-25oz/-/A-12991608#lnk=sametab
...

Sheet Aldi (L)
A1: Ingredient | B1: Quantity (Recipe) | C1: Price | D1: Quantity (Store) | E1: Per Recipe | F1: Link
A3: Baked Feta Pasta - Taryn | O3: 6
A4: Baby Spinach | B4: 1 bag | C4: 2.85 | D4: 5oz | E4: 2.85 | F4: Organic Baby Spinach, 5 oz
A5: Cherry Tomatoes | B5: 1 container | C5: 2.19 | D5: 10oz | E5: 2.19 | F5: Grape Tomatoes 10-oz
A6: Feta Block | B6: 1 block | C6: 3.85 | D6: 8 oz | E6: 3.85 | F6: Emporium Selection Traditional Feta Cheese Block 8-oz
A7: Olive oil | B7: 2 tbsp | C7: 6.25 | D7: 16.9 oz (34 tbsp) | E7: =(2/34)*6.25 -> 0.36764706 | F7: https://www.aldi.us/product/carlini-pure-olive-oil-16-9-fl-oz-0000000000000192
A8: Salt/Pepper | B8: generous amount | C8: =4.05+0.85 -> 4.9 | D8: 26 oz salt, 3 oz pep | E8: =(4.05/30)+(0.85/80) -> 0.145625 | F8: https://www.aldi.us/product/stonemill-iodized-salt-26-oz-0000000000001821 | N8: https://www.aldi.us/product/stonemill-ground-black-pepper-3-oz-0000000000001058
A9: Minced garlic | B9: 2 tbsp | C9: 2.85 | D9: 8oz | E9: =(2/16)*2.85 -> 0.35625 | F9: https://www.aldi.us/product/stonemill-minced-garlic-in-water-8-oz-0000000000001929
A10: Pasta | B10: 8 oz | C10: 2.09 | D10: 16oz | E10: =2.09/2 -> 1.045 | F10: https://www.aldi.us/product/simply-nature-organic-linguine-1-lb-0000000000001535
A11: Totals | C11: =SUM(C4:C10) -> 24.98 | E11: =SUM(E4:E10) -> 10.804522
A12: Recipe Reference: https://thespicegirlkitchen.com/creamy-salmon-pasta/
A14: Overnight Oats - Taryn | O14: 1
A15: Old fashioned oats | B15: 1/4 cup | C15: 4.55 | D15: 42oz (5.25 cups) | E15: =(1/21)*4.55 -> 0.21666667 | F15: https://www.aldi.us/product/millville-old-fashioned-rolled-oats-42-oz-0000000000001533
A16: Greek yogurt | B16: 1/4 cup | C16: 3.29 | D16: 32oz | E16: =3.29/16 -> 0.205625 | F16: https://www.aldi.us/product/friendly-farms-nonfat-plain-greek-yogurt-32-oz-0000000000000020
A17: Milk (2%?) | B17: 1/3 cup | C17: 2.79 | D17: 8 cups | E17: =(1/24)*2.79 -> 0.11625 | F17: https://www.aldi.us/product/friendly-farms-2-milk-64-fl-oz-0000000000001476
A18: Chia Seeds | B18: 2 tsp | C18: 4.09 | D18: 12 oz | E18: =(2/72)*4.09 -> 0.11361111 | F18: https://www.aldi.us/product/simply-nature-chia-seeds-12-oz-0000000000000605
A19: Strawberries | B19: 1/4 cup | C19: 3.09 | D19: 1lb (3 cups) | E19: =3.09/12 -> 0.2575 | F19: https://www.aldi.us/product/strawberries-1-lb-0000000000003798
A20: Honey | B20: 2 tsp | C20: 3.69 | D20: 12 oz | E20: =(2/72)*3.69 -> 0.1025 | F20: https://www.aldi.us/product/berryhill-honey-bear-12-oz-0000000000001030
A21: Totals | C21: =SUM(C15:C20) -> 21.5 | E21: =SUM(E15:E20) -> 1.0121528
A22: Recipe reference: https://www.allrecipes.com/recipe/244251/no-cook-overnight-oatmeal/
A24: Quesidilla - Liliana | O24: 4
A25: Tortilla (Large?) | B25: 8 | C25: 2.35 | D25: 8 | E25: 2.35 | F25: https://www.aldi.us/product/pueblo-lindo-large-burrito-flour-tortillas-8-count-0000000000002386
A26: Butter | B26: 1 tbs | C26: 3.29 | D26: 16 oz | E26: =3.29/32 -> 0.1028125 | F26: https://www.aldi.us/product/countryside-creamery-unsalted-butter-sticks-1-lb-0000000000001861
A27: Chicken breast | B27: 2 breasts | C27: 5.79 | D27: 2 breasts | E27: 5.79 | F27: https://www.aldi.us/product/simply-nature-organic-chicken-breasts-per-lb-0000000000008054
A28: Black beans | B28: 1 can | C28: 0.95 | D28: 1 can | E28: 0.95 | F28: https://www.aldi.us/product/black-beans-15-5-oz-can-0000000000001392
A29: Shredded cheddar cheese | B29: 1 bag | C29: 2.65 | D29: 11 oz | E29: 2.65 | F29: https://www.aldi.us/product/happy-farms-thick-cut-shredded-yellow-cheddar-cheese-11-oz-0000000000009398
A30: Salt/Pepper | B30: 1 tsp | C30: =4.05+0.85 -> 4.9 | D30: 26 oz salt, 3 oz pep | E30: =(4.05/45)+(0.85/123) -> 0.096910569 | F30: Repeat Item
A31: Olive oil (sub with vegetable) | B31: 1 Tbs | C31: 6.25 | D31: 16.9 oz (34 tbsp) | E31: =(1/34)*6.25 -> 0.18382353 | F31: Repeat Item
A32: Totals | C32: =SUM(C25:C31) -> 26.18 | E32: =SUM(E25:E31) -> 12.123547
A33: Recipe Reference:
A35: Taco Soup - Liliana | O35: 6
A36: Ground Beef | B36: 1lb | C36: 6.95 | D36: 1lb | E36: 6.95 | F36: https://www.aldi.us/product/simply-nature-organic-grass-fed-85-lean-ground-beef-1-lb-0000000000001500
A37: Onion (yellow?) | B37: 1 | C37: 2.19 | D37: 5 | E37: =(1/5)*2.19 -> 0.438 | F37: https://www.aldi.us/product/yellow-onions-3-lb-0000000000004002
A38: Diced tomatos | B38: 1 can | C38: 0.99 | D38: 1 can | E38: 0.99 | F38: https://www.aldi.us/product/simply-nature-organic-grass-fed-85-lean-ground-beef-1-lb-0000000000001500
A39: Taco seasoning | B39: 1 packet | C39: 0.55 | D39: 1 packet | E39: 0.55 | F39: https://www.aldi.us/product/casa-mamita-taco-seasoning-mix-1-oz-0000000000001322
A40: Kindey beans | B40: 1 can | C40: 0.95 | D40: 1 can | E40: 0.95 | F40: https://www.aldi.us/product/dakota-s-pride-canned-dark-red-kidney-beans-15-5-oz-0000000000002679
A41: Sweet corn | B41: 1 can | C41: 0.85 | D41: 1 can | E41: 0.85 | F41: https://www.aldi.us/product/happy-harvest-canned-whole-kernel-golden-sweet-corn-15-25-oz-0000000000001645
A42: Salt/Pepper | B42: A pinch | C42: =4.05+0.85 -> 4.9 | D42: 26 oz salt, 3 oz pep | E42: =(4.05/45)+(0.85/123) -> 0.096910569 | F42: Repeat Item
A43: Shredded cheddar cheese | B43: 1.5 cup bag | C43: =C29 -> 2.65 | D43: =D29 -> 11 oz | E43: =E29*2 -> 5.3 | F43: Repeat Item
A44: Fritos | B44: half bag | C44: 1.89 | D44: 9.25 oz | E44: =1.89/13 -> 0.14538462 | F44: https://www.aldi.us/product/clancy-s-corn-chips-9-25-oz-0000000000001790
...

Sheet Walmart (L)
A1: Ingredient | B1: Quantity (Recipe) | C1: Price | D1: Quantity (Store) | E1: Per Recipe | F1: Link
A3: Baked Feta Pasta - Taryn | O3: 6
A4: Baby Spinach | B4: 1 bag | C4: 2.18 | D4: 1 bag | E4: 2.18 | F4: Marketside Fresh Baby Spinach 6-oz Bag Fresh
A5: Cherry Tomatoes | B5: 1 container | C5: 2.63 | D5: 1 pint | E5: 2.63 | F5: Sunset Angel Sweet Tomatoes 1-Pint Package Fresh
A6: Feta Block | B6: 1 block | C6: 5.46 | D6: 8 oz | E6: 5.46 | F6: President All Natural Feta Cheese Block 8-oz Refrigerated
A7: Olive oil | B7: 2 tbsp | C7: 5.94 | D7: 34 Tbsp | E7: =(2/34)*5.94 -> 0.34941176 | F7: Great Value Classic Olive Oil 17-fl-oz
A8: Salt/Pepper | B8: generous amount | C8: 1.94 | D8: 1.5g | E8: 0.01 | F8: Great Value Black Pepper Iodized Salt 5 25-oz
A9: Minced garlic | B9: 2 tbsp | C9: 1.87 | D9: 7.33 Tbsp | E9: =(2/7.33)*1.87 -> 0.51023192 | F9: Spice World Minced Garlic Jar 4.5-oz
A10: Pasta | B10: 8 oz | C10: 0.98 | D10: 16oz | E10: =0.5*0.98 -> 0.49 | F10: Great Value Linguine 16-oz
A11: Totals | C11: =SUM(C4:C10) -> 21 | E11: =SUM(E4:E10) -> 11.629644
A12: Recipe Reference: https://thespicegirlkitchen.com/creamy-salmon-pasta/
A14: Overnight Oats - Taryn | O14: 1
